Error in sys.excepthook:
Traceback (most recent call last):
  File "/coc/testnvme/pputta7/mambaforge/envs/lmnav/lib/python3.9/linecache.py", line 72, in checkcache
    stat = os.stat(fullname)
KeyboardInterrupt
Original exception was:
Traceback (most recent call last):
  File "/coc/testnvme/pputta7/projects/lm-nav/lmnav/bc_train.py", line 355, in <module>
    main()
  File "/coc/testnvme/pputta7/projects/lm-nav/lmnav/bc_train.py", line 349, in main
    trainer.train()
  File "/coc/testnvme/pputta7/projects/lm-nav/lmnav/bc_train.py", line 224, in train
    stats = self.train_epoch(epoch)
  File "/coc/testnvme/pputta7/projects/lm-nav/lmnav/bc_train.py", line 163, in train_epoch
    episode_stats, episodes = zip(*[self.data_conn.recv() for _ in range(min_episodes)])
  File "/coc/testnvme/pputta7/projects/lm-nav/lmnav/bc_train.py", line 163, in <listcomp>
    episode_stats, episodes = zip(*[self.data_conn.recv() for _ in range(min_episodes)])
  File "/coc/testnvme/pputta7/mambaforge/envs/lmnav/lib/python3.9/multiprocessing/connection.py", line 250, in recv
    buf = self._recv_bytes()
  File "/coc/testnvme/pputta7/mambaforge/envs/lmnav/lib/python3.9/multiprocessing/connection.py", line 414, in _recv_bytes
    buf = self._recv(4)
  File "/coc/testnvme/pputta7/mambaforge/envs/lmnav/lib/python3.9/multiprocessing/connection.py", line 379, in _recv
    chunk = read(handle, remaining)
KeyboardInterrupt